Workbook

Sheet Parametri
A1: Parametri sconti e IVA – modificare solo le celle gialle
A3: Data di riferimento per il calcolo della scadenza | B3: =TODAY() -> 46293 | C3: Formula: si aggiorna ogni giorno. Si può sostituire con una data fissa.
A4: Aliquota IVA predefinita | B4: 0.1 | C4: Indicata da Salvatore. Le eccezioni si scrivono a mano nella colonna IVA del foglio prezzi.
A7: Fasce di sconto sul prezzo al pubblico
A8: Fascia | B8: Scadenza almeno a (mesi) | C8: Sconto
A9: Fascia 1 – scadenza lunga | B9: 8 | C9: 0.38
A10: Fascia 2 – scadenza media | B10: 6 | C10: 0.4
A11: Fascia 3 – scadenza breve (sotto la fascia 2) | B11: 0 | C11: 0.45
A13: Valori indicati da Salvatore il 28/09/2026: almeno 8 mesi 38%, da 6 a meno di 8 mesi 40%, sotto 6 mesi 45%.
A14: Il prezzo del listino è il prezzo al pubblico IVA inclusa; il prezzo farmacia IVA esclusa = prezzo al pubblico × (1 − sconto) ÷ (1 + IVA).
A15: Se la somma dei lotti non coincide con il totale del prodotto, tutto il prodotto è mancante temporaneamente. I lotti senza scadenza risultano mancanti; quelli scaduti non sono vendibili.

Sheet Anteprima prezzi
A1: Codice | B1: Prodotto | C1: Lotto | D1: Scadenza | E1: Pezzi | F1: Mesi residui | G1: Stato | H1: Prezzo pubblico IVA incl. | I1: IVA | J1: Prezzo pubblico IVA escl. | K1: Sconto | L1: Prezzo farmacia IVA incl. | M1: Prezzo farmacia IVA escl. | N1: Valore lotto IVA escl. | O1: Totale prodotto dichiarato | P1: Somma lotti
A2: 983389420 | B2: ADEGEN 10BUST | C2: L-03 | D2: 46752 | E2: 616 | F2: =IF(D2="","",ROUND((D2-Parametri!$B$3)/30.4375,1)) -> 15.1 | G2: =IF(P2<>O2,"Mancante temporaneamente (difformità)",IF(D2="","Mancante (senza scadenza)",IF(D2<Parametri!$B$3,"Scaduto",IF(H2="","Prezzo mancante","Disponibile")))) -> Disponibile | H2: 22.5 | I2: =Parametri!$B$4 -> 0.1 | J2: =IF(H2="","",ROUND(H2/(1+I2),2)) -> 20.45 | K2: =IF(G2<>"Disponibile","",IF(D2>=EDATE(Parametri!$B$3,Parametri!$B$9),Parametri!$C$9,IF(D2>=EDATE(Parametri!$B$3,Parametri!$B$10),Parametri!$C$10,Parametri!$C$11))) -> 0.38 | L2: =IF(K2="","",ROUND(H2*(1-K2),2)) -> 13.95 | M2: =IF(K2="","",ROUND(L2/(1+I2),2)) -> 12.68 | N2: =IF(M2="","",E2*M2) -> 7810.88 | O2: 616 | P2: =SUMIF($A$2:$A$200,A2,$E$2:$E$200) -> 616
A3: 939130706 | B3: ALVIOS 30CPR | C3: 2500005 | D3: 46812 | E3: 611 | F3: =IF(D3="","",ROUND((D3-Parametri!$B$3)/30.4375,1)) -> 17.1 | G3: =IF(P3<>O3,"Mancante temporaneamente (difformità)",IF(D3="","Mancante (senza scadenza)",IF(D3<Parametri!$B$3,"Scaduto",IF(H3="","Prezzo mancante","Disponibile")))) -> Disponibile | H3: 31.5 | I3: =Parametri!$B$4 -> 0.1 | J3: =IF(H3="","",ROUND(H3/(1+I3),2)) -> 28.64 | K3: =IF(G3<>"Disponibile","",IF(D3>=EDATE(Parametri!$B$3,Parametri!$B$9),Parametri!$C$9,IF(D3>=EDATE(Parametri!$B$3,Parametri!$B$10),Parametri!$C$10,Parametri!$C$11))) -> 0.38 | L3: =IF(K3="","",ROUND(H3*(1-K3),2)) -> 19.53 | M3: =IF(K3="","",ROUND(L3/(1+I3),2)) -> 17.75 | N3: =IF(M3="","",E3*M3) -> 10845.25 | O3: 611 | P3: =SUMIF($A$2:$A$200,A3,$E$2:$E$200) -> 611
A4: 921178240 | B4: ANGEREX 600 20CPR | C4: A4284 | D4: 46660 | E4: 1462 | F4: =IF(D4="","",ROUND((D4-Parametri!$B$3)/30.4375,1)) -> 12.1 | G4: =IF(P4<>O4,"Mancante temporaneamente (difformità)",IF(D4="","Mancante (senza scadenza)",IF(D4<Parametri!$B$3,"Scaduto",IF(H4="","Prezzo mancante","Disponibile")))) -> Disponibile | H4: 30 | I4: =Parametri!$B$4 -> 0.1 | J4: =IF(H4="","",ROUND(H4/(1+I4),2)) -> 27.27 | K4: =IF(G4<>"Disponibile","",IF(D4>=EDATE(Parametri!$B$3,Parametri!$B$9),Parametri!$C$9,IF(D4>=EDATE(Parametri!$B$3,Parametri!$B$10),Parametri!$C$10,Parametri!$C$11))) -> 0.38 | L4: =IF(K4="","",ROUND(H4*(1-K4),2)) -> 18.6 | M4: =IF(K4="","",ROUND(L4/(1+I4),2)) -> 16.91 | N4: =IF(M4="","",E4*M4) -> 24722.42 | O4: 6347 | P4: =SUMIF($A$2:$A$200,A4,$E$2:$E$200) -> 6347
A5: 921178240 | B5: ANGEREX 600 20CPR | C5: a6082 | D5: 47238 | E5: 4885 | F5: =IF(D5="","",ROUND((D5-Parametri!$B$3)/30.4375,1)) -> 31 | G5: =IF(P5<>O5,"Mancante temporaneamente (difformità)",IF(D5="","Mancante (senza scadenza)",IF(D5<Parametri!$B$3,"Scaduto",IF(H5="","Prezzo mancante","Disponibile")))) -> Disponibile | H5: 30 | I5: =Parametri!$B$4 -> 0.1 | J5: =IF(H5="","",ROUND(H5/(1+I5),2)) -> 27.27 | K5: =IF(G5<>"Disponibile","",IF(D5>=EDATE(Parametri!$B$3,Parametri!$B$9),Parametri!$C$9,IF(D5>=EDATE(Parametri!$B$3,Parametri!$B$10),Parametri!$C$10,Parametri!$C$11))) -> 0.38 | L5: =IF(K5="","",ROUND(H5*(1-K5),2)) -> 18.6 | M5: =IF(K5="","",ROUND(L5/(1+I5),2)) -> 16.91 | N5: =IF(M5="","",E5*M5) -> 82605.35 | O5: 6347 | P5: =SUMIF($A$2:$A$200,A5,$E$2:$E$200) -> 6347
A6: 977259187 | B6: APSTEROL 50CPR | C6: 6215 | D6: 46568 | E6: 650 | F6: =IF(D6="","",ROUND((D6-Parametri!$B$3)/30.4375,1)) -> 9 | G6: =IF(P6<>O6,"Mancante temporaneamente (difformità)",IF(D6="","Mancante (senza scadenza)",IF(D6<Parametri!$B$3,"Scaduto",IF(H6="","Prezzo mancante","Disponibile")))) -> Disponibile | H6: 52 | I6: =Parametri!$B$4 -> 0.1 | J6: =IF(H6="","",ROUND(H6/(1+I6),2)) -> 47.27 | K6: =IF(G6<>"Disponibile","",IF(D6>=EDATE(Parametri!$B$3,Parametri!$B$9),Parametri!$C$9,IF(D6>=EDATE(Parametri!$B$3,Parametri!$B$10),Parametri!$C$10,Parametri!$C$11))) -> 0.38 | L6: =IF(K6="","",ROUND(H6*(1-K6),2)) -> 32.24 | M6: =IF(K6="","",ROUND(L6/(1+I6),2)) -> 29.31 | N6: =IF(M6="","",E6*M6) -> 19051.5 | O6: 650 | P6: =SUMIF($A$2:$A$200,A6,$E$2:$E$200) -> 650
A7: 950220095 | B7: ASERA 20CPR | C7: 6709 | D7: 47149 | E7: 526 | F7: =IF(D7="","",ROUND((D7-Parametri!$B$3)/30.4375,1)) -> 28.1 | G7: =IF(P7<>O7,"Mancante temporaneamente (difformità)",IF(D7="","Mancante (senza scadenza)",IF(D7<Parametri!$B$3,"Scaduto",IF(H7="","Prezzo mancante","Disponibile")))) -> Disponibile | H7: 25 | I7: =Parametri!$B$4 -> 0.1 | J7: =IF(H7="","",ROUND(H7/(1+I7),2)) -> 22.73 | K7: =IF(G7<>"Disponibile","",IF(D7>=EDATE(Parametri!$B$3,Parametri!$B$9),Parametri!$C$9,IF(D7>=EDATE(Parametri!$B$3,Parametri!$B$10),Parametri!$C$10,Parametri!$C$11))) -> 0.38 | L7: =IF(K7="","",ROUND(H7*(1-K7),2)) -> 15.5 | M7: =IF(K7="","",ROUND(L7/(1+I7),2)) -> 14.09 | N7: =IF(M7="","",E7*M7) -> 7411.34 | O7: 526 | P7: =SUMIF($A$2:$A$200,A7,$E$2:$E$200) -> 526
A8: 923359463 | B8: ASERA GOCCE 10ML | C8: 6710 | D8: 47087 | E8: 3420 | F8: =IF(D8="","",ROUND((D8-Parametri!$B$3)/30.4375,1)) -> 26.1 | G8: =IF(P8<>O8,"Mancante temporaneamente (difformità)",IF(D8="","Mancante (senza scadenza)",IF(D8<Parametri!$B$3,"Scaduto",IF(H8="","Prezzo mancante","Disponibile")))) -> Disponibile | H8: 25 | I8: =Parametri!$B$4 -> 0.1 | J8: =IF(H8="","",ROUND(H8/(1+I8),2)) -> 22.73 | K8: =IF(G8<>"Disponibile","",IF(D8>=EDATE(Parametri!$B$3,Parametri!$B$9),Parametri!$C$9,IF(D8>=EDATE(Parametri!$B$3,Parametri!$B$10),Parametri!$C$10,Parametri!$C$11))) -> 0.38 | L8: =IF(K8="","",ROUND(H8*(1-K8),2)) -> 15.5 | M8: =IF(K8="","",ROUND(L8/(1+I8),2)) -> 14.09 | N8: =IF(M8="","",E8*M8) -> 48187.8 | O8: 3420 | P8: =SUMIF($A$2:$A$200,A8,$E$2:$E$200) -> 3420
A9: 971302942 | B9: BIOUMOREX 30CPS | C9: 2500040 | D9: 46446 | E9: 794 | F9: =IF(D9="","",ROUND((D9-Parametri!$B$3)/30.4375,1)) -> 5 | G9: =IF(P9<>O9,"Mancante temporaneamente (difformità)",IF(D9="","Mancante (senza scadenza)",IF(D9<Parametri!$B$3,"Scaduto",IF(H9="","Prezzo mancante","Disponibile")))) -> Disponibile | H9: 31 | I9: =Parametri!$B$4 -> 0.1 | J9: =IF(H9="","",ROUND(H9/(1+I9),2)) -> 28.18 | K9: =IF(G9<>"Disponibile","",IF(D9>=EDATE(Parametri!$B$3,Parametri!$B$9),Parametri!$C$9,IF(D9>=EDATE(Parametri!$B$3,Parametri!$B$10),Parametri!$C$10,Parametri!$C$11))) -> 0.45 | L9: =IF(K9="","",ROUND(H9*(1-K9),2)) -> 17.05 | M9: =IF(K9="","",ROUND(L9/(1+I9),2)) -> 15.5 | N9: =IF(M9="","",E9*M9) -> 12307 | O9: 794 | P9: =SUMIF($A$2:$A$200,A9,$E$2:$E$200) -> 794
A10: 986005460 | B10: ELIVID 60CPR | C10: l-03 | D10: 46507 | E10: 297 | F10: =IF(D10="","",ROUND((D10-Parametri!$B$3)/30.4375,1)) -> 7 | G10: =IF(P10<>O10,"Mancante temporaneamente (difformità)",IF(D10="","Mancante (senza scadenza)",IF(D10<Parametri!$B$3,"Scaduto",IF(H10="","Prezzo mancante","Disponibile")))) -> Mancante temporaneamente (difformità) | H10: 21 | I10: =Parametri!$B$4 -> 0.1 | J10: =IF(H10="","",ROUND(H10/(1+I10),2)) -> 19.09 | K10: =IF(G10<>"Disponibile","",IF(D10>=EDATE(Parametri!$B$3,Parametri!$B$9),Parametri!$C$9,IF(D10>=EDATE(Parametri!$B$3,Parametri!$B$10),Parametri!$C$10,Parametri!$C$11))) | L10: =IF(K10="","",ROUND(H10*(1-K10),2)) | M10: =IF(K10="","",ROUND(L10/(1+I10),2)) | N10: =IF(M10="","",E10*M10) | O10: 2314 | P10: =SUMIF($A$2:$A$200,A10,$E$2:$E$200) -> 2317
A11: 986005460 | B11: ELIVID 60CPR | C11: l-04 | D11: 47299 | E11: 2020 | F11: =IF(D11="","",ROUND((D11-Parametri!$B$3)/30.4375,1)) -> 33.1 | G11: =IF(P11<>O11,"Mancante temporaneamente (difformità)",IF(D11="","Mancante (senza scadenza)",IF(D11<Parametri!$B$3,"Scaduto",IF(H11="","Prezzo mancante","Disponibile")))) -> Mancante temporaneamente (difformità) | H11: 21 | I11: =Parametri!$B$4 -> 0.1 | J11: =IF(H11="","",ROUND(H11/(1+I11),2)) -> 19.09 | K11: =IF(G11<>"Disponibile","",IF(D11>=EDATE(Parametri!$B$3,Parametri!$B$9),Parametri!$C$9,IF(D11>=EDATE(Parametri!$B$3,Parametri!$B$10),Parametri!$C$10,Parametri!$C$11))) | L11: =IF(K11="","",ROUND(H11*(1-K11),2)) | M11: =IF(K11="","",ROUND(L11/(1+I11),2)) | N11: =IF(M11="","",E11*M11) | O11: 2314 | P11: =SUMIF($A$2:$A$200,A11,$E$2:$E$200) -> 2317
A12: 984734400 | B12: EMANGIOVAX 30CPR | C12: A5492 | D12: 46752 | E12: 606 | F12: =IF(D12="","",ROUND((D12-Parametri!$B$3)/30.4375,1)) -> 15.1 | G12: =IF(P12<>O12,"Mancante temporaneamente (difformità)",IF(D12="","Mancante (senza scadenza)",IF(D12<Parametri!$B$3,"Scaduto",IF(H12="","Prezzo mancante","Disponibile")))) -> Disponibile | H12: 27 | I12: =Parametri!$B$4 -> 0.1 | J12: =IF(H12="","",ROUND(H12/(1+I12),2)) -> 24.55 | K12: =IF(G12<>"Disponibile","",IF(D12>=EDATE(Parametri!$B$3,Parametri!$B$9),Parametri!$C$9,IF(D12>=EDATE(Parametri!$B$3,Parametri!$B$10),Parametri!$C$10,Parametri!$C$11))) -> 0.38 | L12: =IF(K12="","",ROUND(H12*(1-K12),2)) -> 16.74 | M12: =IF(K12="","",ROUND(L12/(1+I12),2)) -> 15.22 | N12: =IF(M12="","",E12*M12) -> 9223.32 | O12: 3448 | P12: =SUMIF($A$2:$A$200,A12,$E$2:$E$200) -> 3448
A13: 984734400 | B13: EMANGIOVAX 30CPR | C13: a6137 | D13: 46934 | E13: 2842 | F13: =IF(D13="","",ROUND((D13-Parametri!$B$3)/30.4375,1)) -> 21.1 | G13: =IF(P13<>O13,"Mancante temporaneamente (difformità)",IF(D13="","Mancante (senza scadenza)",IF(D13<Parametri!$B$3,"Scaduto",IF(H13="","Prezzo mancante","Disponibile")))) -> Disponibile | H13: 27 | I13: =Parametri!$B$4 -> 0.1 | J13: =IF(H13="","",ROUND(H13/(1+I13),2)) -> 24.55 | K13: =IF(G13<>"Disponibile","",IF(D13>=EDATE(Parametri!$B$3,Parametri!$B$9),Parametri!$C$9,IF(D13>=EDATE(Parametri!$B$3,Parametri!$B$10),Parametri!$C$10,Parametri!$C$11))) -> 0.38 | L13: =IF(K13="","",ROUND(H13*(1-K13),2)) -> 16.74 | M13: =IF(K13="","",ROUND(L13/(1+I13),2)) -> 15.22 | N13: =IF(M13="","",E13*M13) -> 43255.24 | O13: 3448 | P13: =SUMIF($A$2:$A$200,A13,$E$2:$E$200) -> 3448
... A16: 950071415 | B16: FORTIRENE 200 200ML | C16: 5603 | D16: 46418 | E16: 279 | F16: =IF(D16="","",ROUND((D16-Parametri!$B$3)/30.4375,1)) -> 4.1 | G16: =IF(P16<>O16,"Mancante temporaneamente (difformità)",IF(D16="","Mancante (senza scadenza)",IF(D16<Parametri!$B$3,"Scaduto",IF(H16="","Prezzo mancante","Disponibile")))) -> Disponibile | H16: 27 | I16: =Parametri!$B$4 -> 0.1 | J16: =IF(H16="","",ROUND(H16/(1+I16),2)) -> 24.55 | K16: =IF(G16<>"Disponibile","",IF(D16>=EDATE(Parametri!$B$3,Parametri!$B$9),Parametri!$C$9,IF(D16>=EDATE(Parametri!$B$3,Parametri!$B$10),Parametri!$C$10,Parametri!$C$11))) -> 0.45 | L16: =IF(K16="","",ROUND(H16*(1-K16),2)) -> 14.85 | M16: =IF(K16="","",ROUND(L16/(1+I16),2)) -> 13.5 | N16: =IF(M16="","",E16*M16) -> 3766.5 | O16: 279 | P16: =SUMIF($A$2:$A$200,A16,$E$2:$E$200) -> 279
A17: 989877079 | B17: INFANTUSS 200ML | C17: 5346 | D17: 46387 | E17: 1006 | F17: =IF(D17="","",ROUND((D17-Parametri!$B$3)/30.4375,1)) -> 3.1 | G17: =IF(P17<>O17,"Mancante temporaneamente (difformità)",IF(D17="","Mancante (senza scadenza)",IF(D17<Parametri!$B$3,"Scaduto",IF(H17="","Prezzo mancante","Disponibile")))) -> Prezzo mancante | I17: =Parametri!$B$4 -> 0.1 | J17: =IF(H17="","",ROUND(H17/(1+I17),2)) | K17: =IF(G17<>"Disponibile","",IF(D17>=EDATE(Parametri!$B$3,Parametri!$B$9),Parametri!$C$9,IF(D17>=EDATE(Parametri!$B$3,Parametri!$B$10),Parametri!$C$10,Parametri!$C$11))) | L17: =IF(K17="","",ROUND(H17*(1-K17),2)) | M17: =IF(K17="","",ROUND(L17/(1+I17),2)) | N17: =IF(M17="","",E17*M17) | O17: 1006 | P17: =SUMIF($A$2:$A$200,A17,$E$2:$E$200) -> 1006
A18: 973362813 | B18: LACTOREPENS 60CPR | C18: 2400509 | D18: 46418 | E18: 201 | F18: =IF(D18="","",ROUND((D18-Parametri!$B$3)/30.4375,1)) -> 4.1 | G18: =IF(P18<>O18,"Mancante temporaneamente (difformità)",IF(D18="","Mancante (senza scadenza)",IF(D18<Parametri!$B$3,"Scaduto",IF(H18="","Prezzo mancante","Disponibile")))) -> Disponibile | H18: 65 | I18: =Parametri!$B$4 -> 0.1 | J18: =IF(H18="","",ROUND(H18/(1+I18),2)) -> 59.09 | K18: =IF(G18<>"Disponibile","",IF(D18>=EDATE(Parametri!$B$3,Parametri!$B$9),Parametri!$C$9,IF(D18>=EDATE(Parametri!$B$3,Parametri!$B$10),Parametri!$C$10,Parametri!$C$11))) -> 0.45 | L18: =IF(K18="","",ROUND(H18*(1-K18),2)) -> 35.75 | M18: =IF(K18="","",ROUND(L18/(1+I18),2)) -> 32.5 | N18: =IF(M18="","",E18*M18) -> 6532.5 | O18: 1110 | P18: =SUMIF($A$2:$A$200,A18,$E$2:$E$200) -> 1110
A19: 973362813 | B19: LACTOREPENS 60CPR | C19: 2600169 | D19: 46934 | E19: 909 | F19: =IF(D19="","",ROUND((D19-Parametri!$B$3)/30.4375,1)) -> 21.1 | G19: =IF(P19<>O19,"Mancante temporaneamente (difformità)",IF(D19="","Mancante (senza scadenza)",IF(D19<Parametri!$B$3,"Scaduto",IF(H19="","Prezzo mancante","Disponibile")))) -> Disponibile | H19: 65 | I19: =Parametri!$B$4 -> 0.1 | J19: =IF(H19="","",ROUND(H19/(1+I19),2)) -> 59.09 | K19: =IF(G19<>"Disponibile","",IF(D19>=EDATE(Parametri!$B$3,Parametri!$B$9),Parametri!$C$9,IF(D19>=EDATE(Parametri!$B$3,Parametri!$B$10),Parametri!$C$10,Parametri!$C$11))) -> 0.38 | L19: =IF(K19="","",ROUND(H19*(1-K19),2)) -> 40.3 | M19: =IF(K19="","",ROUND(L19/(1+I19),2)) -> 36.64 | N19: =IF(M19="","",E19*M19) -> 33305.76 | O19: 1110 | P19: =SUMIF($A$2:$A$200,A19,$E$2:$E$200) -> 1110
A20: 921535086 | B20: LINGAM 30CPR | C20: 2400432 | D20: 46783 | E20: 1192 | F20: =IF(D20="","",ROUND((D20-Parametri!$B$3)/30.4375,1)) -> 16.1 | G20: =IF(P20<>O20,"Mancante temporaneamente (difformità)",IF(D20="","Mancante (senza scadenza)",IF(D20<Parametri!$B$3,"Scaduto",IF(H20="","Prezzo mancante","Disponibile")))) -> Disponibile | H20: 50 | I20: =Parametri!$B$4 -> 0.1 | J20: =IF(H20="","",ROUND(H20/(1+I20),2)) -> 45.45 | K20: =IF(G20<>"Disponibile","",IF(D20>=EDATE(Parametri!$B$3,Parametri!$B$9),Parametri!$C$9,IF(D20>=EDATE(Parametri!$B$3,Parametri!$B$10),Parametri!$C$10,Parametri!$C$11))) -> 0.38 | L20: =IF(K20="","",ROUND(H20*(1-K20),2)) -> 31 | M20: =IF(K20="","",ROUND(L20/(1+I20),2)) -> 28.18 | N20: =IF(M20="","",E20*M20) -> 33590.56 | O20: 1192 | P20: =SUMIF($A$2:$A$200,A20,$E$2:$E$200) -> 1192
A21: 975588955 | B21: LONGEREX 30BUST 4G | C21: 5003/31 | D21: 46418 | E21: 432 | F21: =IF(D21="","",ROUND((D21-Parametri!$B$3)/30.4375,1)) -> 4.1 | G21: =IF(P21<>O21,"Mancante temporaneamente (difformità)",IF(D21="","Mancante (senza scadenza)",IF(D21<Parametri!$B$3,"Scaduto",IF(H21="","Prezzo mancante","Disponibile")))) -> Disponibile | H21: 42 | I21: =Parametri!$B$4 -> 0.1 | J21: =IF(H21="","",ROUND(H21/(1+I21),2)) -> 38.18 | K21: =IF(G21<>"Disponibile","",IF(D21>=EDATE(Parametri!$B$3,Parametri!$B$9),Parametri!$C$9,IF(D21>=EDATE(Parametri!$B$3,Parametri!$B$10),Parametri!$C$10,Parametri!$C$11))) -> 0.45 | L21: =IF(K21="","",ROUND(H21*(1-K21),2)) -> 23.1 | M21: =IF(K21="","",ROUND(L21/(1+I21),2)) -> 21 | N21: =IF(M21="","",E21*M21) -> 9072 | O21: 432 | P21: =SUMIF($A$2:$A$200,A21,$E$2:$E$200) -> 432
A22: 990071577 | B22: LONGEREX ATP 20CPS | C22: l-01 | D22: 47177 | E22: 520 | F22: =IF(D22="","",ROUND((D22-Parametri!$B$3)/30.4375,1)) -> 29 | G22: =IF(P22<>O22,"Mancante temporaneamente (difformità)",IF(D22="","Mancante (senza scadenza)",IF(D22<Parametri!$B$3,"Scaduto",IF(H22="","Prezzo mancante","Disponibile")))) -> Disponibile | H22: 30 | I22: =Parametri!$B$4 -> 0.1 | J22: =IF(H22="","",ROUND(H22/(1+I22),2)) -> 27.27 | K22: =IF(G22<>"Disponibile","",IF(D22>=EDATE(Parametri!$B$3,Parametri!$B$9),Parametri!$C$9,IF(D22>=EDATE(Parametri!$B$3,Parametri!$B$10),Parametri!$C$10,Parametri!$C$11))) -> 0.38 | L22: =IF(K22="","",ROUND(H22*(1-K22),2)) -> 18.6 | M22: =IF(K22="","",ROUND(L22/(1+I22),2)) -> 16.91 | N22: =IF(M22="","",E22*M22) -> 8793.2 | O22: 1297 | P22: =SUMIF($A$2:$A$200,A22,$E$2:$E$200) -> 1297
A23: 990071577 | B23: LONGEREX ATP 20CPS | C23: l-02 | D23: 47299 | E23: 777 | F23: =IF(D23="","",ROUND((D23-Parametri!$B$3)/30.4375,1)) -> 33.1 | G23: =IF(P23<>O23,"Mancante temporaneamente (difformità)",IF(D23="","Mancante (senza scadenza)",IF(D23<Parametri!$B$3,"Scaduto",IF(H23="","Prezzo mancante","Disponibile")))) -> Disponibile | H23: 30 | I23: =Parametri!$B$4 -> 0.1 | J23: =IF(H23="","",ROUND(H23/(1+I23),2)) -> 27.27 | K23: =IF(G23<>"Disponibile","",IF(D23>=EDATE(Parametri!$B$3,Parametri!$B$9),Parametri!$C$9,IF(D23>=EDATE(Parametri!$B$3,Parametri!$B$10),Parametri!$C$10,Parametri!$C$11))) -> 0.38 | L23: =IF(K23="","",ROUND(H23*(1-K23),2)) -> 18.6 | M23: =IF(K23="","",ROUND(L23/(1+I23),2)) -> 16.91 | N23: =IF(M23="","",E23*M23) -> 13139.07 | O23: 1297 | P23: =SUMIF($A$2:$A$200,A23,$E$2:$E$200) -> 1297
A24: 925328167 | B24: MICROLIT 20BUST | C24: 5063/04 | D24: 46873 | E24: 4 | F24: =IF(D24="","",ROUND((D24-Parametri!$B$3)/30.4375,1)) -> 19.1 | G24: =IF(P24<>O24,"Mancante temporaneamente (difformità)",IF(D24="","Mancante (senza scadenza)",IF(D24<Parametri!$B$3,"Scaduto",IF(H24="","Prezzo mancante","Disponibile")))) -> Disponibile | H24: 22.5 | I24: =Parametri!$B$4 -> 0.1 | J24: =IF(H24="","",ROUND(H24/(1+I24),2)) -> 20.45 | K24: =IF(G24<>"Disponibile","",IF(D24>=EDATE(Parametri!$B$3,Parametri!$B$9),Parametri!$C$9,IF(D24>=EDATE(Parametri!$B$3,Parametri!$B$10),Parametri!$C$10,Parametri!$C$11))) -> 0.38 | L24: =IF(K24="","",ROUND(H24*(1-K24),2)) -> 13.95 | M24: =IF(K24="","",ROUND(L24/(1+I24),2)) -> 12.68 | N24: =IF(M24="","",E24*M24) -> 50.72 | O24: 1003 | P24: =SUMIF($A$2:$A$200,A24,$E$2:$E$200) -> 1003
A25: 925328167 | B25: MICROLIT 20BUST | C25: 6007/01 | D25: 47149 | E25: 999 | F25: =IF(D25="","",ROUND((D25-Parametri!$B$3)/30.4375,1)) -> 28.1 | G25: =IF(P25<>O25,"Mancante temporaneamente (difformità)",IF(D25="","Mancante (senza scadenza)",IF(D25<Parametri!$B$3,"Scaduto",IF(H25="","Prezzo mancante","Disponibile")))) -> Disponibile | H25: 22.5 | I25: =Parametri!$B$4 -> 0.1 | J25: =IF(H25="","",ROUND(H25/(1+I25),2)) -> 20.45 | K25: =IF(G25<>"Disponibile","",IF(D25>=EDATE(Parametri!$B$3,Parametri!$B$9),Parametri!$C$9,IF(D25>=EDATE(Parametri!$B$3,Parametri!$B$10),Parametri!$C$10,Parametri!$C$11))) -> 0.38 | L25: =IF(K25="","",ROUND(H25*(1-K25),2)) -> 13.95 | M25: =IF(K25="","",ROUND(L25/(1+I25),2)) -> 12.68 | N25: =IF(M25="","",E25*M25) -> 12667.32 | O25: 1003 | P25: =SUMIF($A$2:$A$200,A25,$E$2:$E$200) -> 1003
A26: 983389432 | B26: MODIR 14CPS | C26: md-04 | D26: 46721 | E26: 770 | F26: =IF(D26="","",ROUND((D26-Parametri!$B$3)/30.4375,1)) -> 14.1 | G26: =IF(P26<>O26,"Mancante temporaneamente (difformità)",IF(D26="","Mancante (senza scadenza)",IF(D26<Parametri!$B$3,"Scaduto",IF(H26="","Prezzo mancante","Disponibile")))) -> Disponibile | H26: 20 | I26: =Parametri!$B$4 -> 0.1 | J26: =IF(H26="","",ROUND(H26/(1+I26),2)) -> 18.18 | K26: =IF(G26<>"Disponibile","",IF(D26>=EDATE(Parametri!$B$3,Parametri!$B$9),Parametri!$C$9,IF(D26>=EDATE(Parametri!$B$3,Parametri!$B$10),Parametri!$C$10,Parametri!$C$11))) -> 0.38 | L26: =IF(K26="","",ROUND(H26*(1-K26),2)) -> 12.4 | M26: =IF(K26="","",ROUND(L26/(1+I26),2)) -> 11.27 | N26: =IF(M26="","",E26*M26) -> 8677.9 | O26: 770 | P26: =SUMIF($A$2:$A$200,A26,$E$2:$E$200) -> 770
A27: 984858720 | B27: NEO ALGISIN 20CPR | C27: 5517 | D27: 46843 | E27: 346 | F27: =IF(D27="","",ROUND((D27-Parametri!$B$3)/30.4375,1)) -> 18.1 | G27: =IF(P27<>O27,"Mancante temporaneamente (difformità)",IF(D27="","Mancante (senza scadenza)",IF(D27<Parametri!$B$3,"Scaduto",IF(H27="","Prezzo mancante","Disponibile")))) -> Disponibile | H27: 25.5 | I27: =Parametri!$B$4 -> 0.1 | J27: =IF(H27="","",ROUND(H27/(1+I27),2)) -> 23.18 | K27: =IF(G27<>"Disponibile","",IF(D27>=EDATE(Parametri!$B$3,Parametri!$B$9),Parametri!$C$9,IF(D27>=EDATE(Parametri!$B$3,Parametri!$B$10),Parametri!$C$10,Parametri!$C$11))) -> 0.38 | L27: =IF(K27="","",ROUND(H27*(1-K27),2)) -> 15.81 | M27: =IF(K27="","",ROUND(L27/(1+I27),2)) -> 14.37 | N27: =IF(M27="","",E27*M27) -> 4972.02 | O27: 346 | P27: =SUMIF($A$2:$A$200,A27,$E$2:$E$200) -> 346
A28: 990411959 | B28: NEUROCRIN L 30CPS | C28: L-01 | D28: 47269 | E28: 1241 | F28: =IF(D28="","",ROUND((D28-Parametri!$B$3)/30.4375,1)) -> 32.1 | G28: =IF(P28<>O28,"Mancante temporaneamente (difformità)",IF(D28="","Mancante (senza scadenza)",IF(D28<Parametri!$B$3,"Scaduto",IF(H28="","Prezzo mancante","Disponibile")))) -> Disponibile | H28: 30 | I28: =Parametri!$B$4 -> 0.1 | J28: =IF(H28="","",ROUND(H28/(1+I28),2)) -> 27.27 | K28: =IF(G28<>"Disponibile","",IF(D28>=EDATE(Parametri!$B$3,Parametri!$B$9),Parametri!$C$9,IF(D28>=EDATE(Parametri!$B$3,Parametri!$B$10),Parametri!$C$10,Parametri!$C$11))) -> 0.38 | L28: =IF(K28="","",ROUND(H28*(1-K28),2)) -> 18.6 | M28: =IF(K28="","",ROUND(L28/(1+I28),2)) -> 16.91 | N28: =IF(M28="","",E28*M28) -> 20985.31 | O28: 1241 | P28: =SUMIF($A$2:$A$200,A28,$E$2:$E$200) -> 1241
A29: 923813695 | B29: NEUROPROTEX 15CPR | C29: 2500479 | D29: 47149 | E29: 795 | F29: =IF(D29="","",ROUND((D29-Parametri!$B$3)/30.4375,1)) -> 28.1 | G29: =IF(P29<>O29,"Mancante temporaneamente (difformità)",IF(D29="","Mancante (senza scadenza)",IF(D29<Parametri!$B$3,"Scaduto",IF(H29="","Prezzo mancante","Disponibile")))) -> Disponibile | H29: 27 | I29: =Parametri!$B$4 -> 0.1 | J29: =IF(H29="","",ROUND(H29/(1+I29),2)) -> 24.55 | K29: =IF(G29<>"Disponibile","",IF(D29>=EDATE(Parametri!$B$3,Parametri!$B$9),Parametri!$C$9,IF(D29>=EDATE(Parametri!$B$3,Parametri!$B$10),Parametri!$C$10,Parametri!$C$11))) -> 0.38 | L29: =IF(K29="","",ROUND(H29*(1-K29),2)) -> 16.74 | M29: =IF(K29="","",ROUND(L29/(1+I29),2)) -> 15.22 | N29: =IF(M29="","",E29*M29) -> 12099.9 | O29: 10215 | P29: =SUMIF($A$2:$A$200,A29,$E$2:$E$200) -> 10215
... A32: 971677188 | B32: NEUROSTART 20CPR | C32: 2500478 | D32: 47149 | E32: 8067 | F32: =IF(D32="","",ROUND((D32-Parametri!$B$3)/30.4375,1)) -> 28.1 | G32: =IF(P32<>O32,"Mancante temporaneamente (difformità)",IF(D32="","Mancante (senza scadenza)",IF(D32<Parametri!$B$3,"Scaduto",IF(H32="","Prezzo mancante","Disponibile")))) -> Disponibile | H32: 27 | I32: =Parametri!$B$4 -> 0.1 | J32: =IF(H32="","",ROUND(H32/(1+I32),2)) -> 24.55 | K32: =IF(G32<>"Disponibile","",IF(D32>=EDATE(Parametri!$B$3,Parametri!$B$9),Parametri!$C$9,IF(D32>=EDATE(Parametri!$B$3,Parametri!$B$10),Parametri!$C$10,Parametri!$C$11))) -> 0.38 | L32: =IF(K32="","",ROUND(H32*(1-K32),2)) -> 16.74 | M32: =IF(K32="","",ROUND(L32/(1+I32),2)) -> 15.22 | N32: =IF(M32="","",E32*M32) -> 122779.74 | O32: 8067 | P32: =SUMIF($A$2:$A$200,A32,$E$2:$E$200) -> 8067
A33: 989630734 | B33: NIAGARA COLLUTORIO 200ML | C33: 21624-1 | D33: 46387 | E33: 193 | F33: =IF(D33="","",ROUND((D33-Parametri!$B$3)/30.4375,1)) -> 3.1 | G33: =IF(P33<>O33,"Mancante temporaneamente (difformità)",IF(D33="","Mancante (senza scadenza)",IF(D33<Parametri!$B$3,"Scaduto",IF(H33="","Prezzo mancante","Disponibile")))) -> Prezzo mancante | I33: =Parametri!$B$4 -> 0.1 | J33: =IF(H33="","",ROUND(H33/(1+I33),2)) | K33: =IF(G33<>"Disponibile","",IF(D33>=EDATE(Parametri!$B$3,Parametri!$B$9),Parametri!$C$9,IF(D33>=EDATE(Parametri!$B$3,Parametri!$B$10),Parametri!$C$10,Parametri!$C$11))) | L33: =IF(K33="","",ROUND(H33*(1-K33),2)) | M33: =IF(K33="","",ROUND(L33/(1+I33),2)) | N33: =IF(M33="","",E33*M33) | O33: 193 | P33: =SUMIF($A$2:$A$200,A33,$E$2:$E$200) -> 193
A34: 987038534 | B34: OMEGAREX 20STICK PACK | C34: 5660 | D34: 46418 | E34: 461 | F34: =IF(D34="","",ROUND((D34-Parametri!$B$3)/30.4375,1)) -> 4.1 | G34: =IF(P34<>O34,"Mancante temporaneamente (difformità)",IF(D34="","Mancante (senza scadenza)",IF(D34<Parametri!$B$3,"Scaduto",IF(H34="","Prezzo mancante","Disponibile")))) -> Prezzo mancante | I34: =Parametri!$B$4 -> 0.1 | J34: =IF(H34="","",ROUND(H34/(1+I34),2)) | K34: =IF(G34<>"Disponibile","",IF(D34>=EDATE(Parametri!$B$3,Parametri!$B$9),Parametri!$C$9,IF(D34>=EDATE(Parametri!$B$3,Parametri!$B$10),Parametri!$C$10,Parametri!$C$11))) | L34: =IF(K34="","",ROUND(H34*(1-K34),2)) | M34: =IF(K34="","",ROUND(L34/(1+I34),2)) | N34: =IF(M34="","",E34*M34) | O34: 461 | P34: =SUMIF($A$2:$A$200,A34,$E$2:$E$200) -> 461
A35: 951330404 | B35: PEAREX 20CPR | C35: l-02 | D35: 47149 | E35: 836 | F35: =IF(D35="","",ROUND((D35-Parametri!$B$3)/30.4375,1)) -> 28.1 | G35: =IF(P35<>O35,"Mancante temporaneamente (difformità)",IF(D35="","Mancante (senza scadenza)",IF(D35<Parametri!$B$3,"Scaduto",IF(H35="","Prezzo mancante","Disponibile")))) -> Disponibile | H35: 28.5 | I35: =Parametri!$B$4 -> 0.1 | J35: =IF(H35="","",ROUND(H35/(1+I35),2)) -> 25.91 | K35: =IF(G35<>"Disponibile","",IF(D35>=EDATE(Parametri!$B$3,Parametri!$B$9),Parametri!$C$9,IF(D35>=EDATE(Parametri!$B$3,Parametri!$B$10),Parametri!$C$10,Parametri!$C$11))) -> 0.38 | L35: =IF(K35="","",ROUND(H35*(1-K35),2)) -> 17.67 | M35: =IF(K35="","",ROUND(L35/(1+I35),2)) -> 16.06 | N35: =IF(M35="","",E35*M35) -> 13426.16 | O35: 5230 | P35: =SUMIF($A$2:$A$200,A35,$E$2:$E$200) -> 5230
A36: 951330404 | B36: PEAREX 20CPR | C36: L-03 | D36: 47269 | E36: 4394 | F36: =IF(D36="","",ROUND((D36-Parametri!$B$3)/30.4375,1)) -> 32.1 | G36: =IF(P36<>O36,"Mancante temporaneamente (difformità)",IF(D36="","Mancante (senza scadenza)",IF(D36<Parametri!$B$3,"Scaduto",IF(H36="","Prezzo mancante","Disponibile")))) -> Disponibile | H36: 28.5 | I36: =Parametri!$B$4 -> 0.1 | J36: =IF(H36="","",ROUND(H36/(1+I36),2)) -> 25.91 | K36: =IF(G36<>"Disponibile","",IF(D36>=EDATE(Parametri!$B$3,Parametri!$B$9),Parametri!$C$9,IF(D36>=EDATE(Parametri!$B$3,Parametri!$B$10),Parametri!$C$10,Parametri!$C$11))) -> 0.38 | L36: =IF(K36="","",ROUND(H36*(1-K36),2)) -> 17.67 | M36: =IF(K36="","",ROUND(L36/(1+I36),2)) -> 16.06 | N36: =IF(M36="","",E36*M36) -> 70567.64 | O36: 5230 | P36: =SUMIF($A$2:$A$200,A36,$E$2:$E$200) -> 5230
A37: 951048204 | B37: POSI' 30BUST | C37: l-02 | D37: 47026 | E37: 2330 | F37: =IF(D37="","",ROUND((D37-Parametri!$B$3)/30.4375,1)) -> 24.1 | G37: =IF(P37<>O37,"Mancante temporaneamente (difformità)",IF(D37="","Mancante (senza scadenza)",IF(D37<Parametri!$B$3,"Scaduto",IF(H37="","Prezzo mancante","Disponibile")))) -> Disponibile | H37: 22.5 | I37: =Parametri!$B$4 -> 0.1 | J37: =IF(H37="","",ROUND(H37/(1+I37),2)) -> 20.45 | K37: =IF(G37<>"Disponibile","",IF(D37>=EDATE(Parametri!$B$3,Parametri!$B$9),Parametri!$C$9,IF(D37>=EDATE(Parametri!$B$3,Parametri!$B$10),Parametri!$C$10,Parametri!$C$11))) -> 0.38 | L37: =IF(K37="","",ROUND(H37*(1-K37),2)) -> 13.95 | M37: =IF(K37="","",ROUND(L37/(1+I37),2)) -> 12.68 | N37: =IF(M37="","",E37*M37) -> 29544.4 | O37: 4330 | P37: =SUMIF($A$2:$A$200,A37,$E$2:$E$200) -> 4330
A38: 951048204 | B38: POSI' 30BUST | C38: l-03 | D38: 47391 | E38: 2000 | F38: =IF(D38="","",ROUND((D38-Parametri!$B$3)/30.4375,1)) -> 36.1 | G38: =IF(P38<>O38,"Mancante temporaneamente (difformità)",IF(D38="","Mancante (senza scadenza)",IF(D38<Parametri!$B$3,"Scaduto",IF(H38="","Prezzo mancante","Disponibile")))) -> Disponibile | H38: 22.5 | I38: =Parametri!$B$4 -> 0.1 | J38: =IF(H38="","",ROUND(H38/(1+I38),2)) -> 20.45 | K38: =IF(G38<>"Disponibile","",IF(D38>=EDATE(Parametri!$B$3,Parametri!$B$9),Parametri!$C$9,IF(D38>=EDATE(Parametri!$B$3,Parametri!$B$10),Parametri!$C$10,Parametri!$C$11))) -> 0.38 | L38: =IF(K38="","",ROUND(H38*(1-K38),2)) -> 13.95 | M38: =IF(K38="","",ROUND(L38/(1+I38),2)) -> 12.68 | N38: =IF(M38="","",E38*M38) -> 25360 | O38: 4330 | P38: =SUMIF($A$2:$A$200,A38,$E$2:$E$200) -> 4330
A39: 990071589 | B39: POSI' VITA 30CPR | C39: l-01 | D39: 47177 | E39: 663 | F39: =IF(D39="","",ROUND((D39-Parametri!$B$3)/30.4375,1)) -> 29 | G39: =IF(P39<>O39,"Mancante temporaneamente (difformità)",IF(D39="","Mancante (senza scadenza)",IF(D39<Parametri!$B$3,"Scaduto",IF(H39="","Prezzo mancante","Disponibile")))) -> Disponibile | H39: 22.5 | I39: =Parametri!$B$4 -> 0.1 | J39: =IF(H39="","",ROUND(H39/(1+I39),2)) -> 20.45 | K39: =IF(G39<>"Disponibile","",IF(D39>=EDATE(Parametri!$B$3,Parametri!$B$9),Parametri!$C$9,IF(D39>=EDATE(Parametri!$B$3,Parametri!$B$10),Parametri!$C$10,Parametri!$C$11))) -> 0.38 | L39: =IF(K39="","",ROUND(H39*(1-K39),2)) -> 13.95 | M39: =IF(K39="","",ROUND(L39/(1+I39),2)) -> 12.68 | N39: =IF(M39="","",E39*M39) -> 8406.84 | O39: 663 | P39: =SUMIF($A$2:$A$200,A39,$E$2:$E$200) -> 663
A40: 973605292 | B40: PRIMUS 10FLACONCINI | C40: 6712 | D40: 46904 | E40: 1364 | F40: =IF(D40="","",ROUND((D40-Parametri!$B$3)/30.4375,1)) -> 20.1 | G40: =IF(P40<>O40,"Mancante temporaneamente (difformità)",IF(D40="","Mancante (senza scadenza)",IF(D40<Parametri!$B$3,"Scaduto",IF(H40="","Prezzo mancante","Disponibile")))) -> Disponibile | H40: 25 | I40: =Parametri!$B$4 -> 0.1 | J40: =IF(H40="","",ROUND(H40/(1+I40),2)) -> 22.73 | K40: =IF(G40<>"Disponibile","",IF(D40>=EDATE(Parametri!$B$3,Parametri!$B$9),Parametri!$C$9,IF(D40>=EDATE(Parametri!$B$3,Parametri!$B$10),Parametri!$C$10,Parametri!$C$11))) -> 0.38 | L40: =IF(K40="","",ROUND(H40*(1-K40),2)) -> 15.5 | M40: =IF(K40="","",ROUND(L40/(1+I40),2)) -> 14.09 | N40: =IF(M40="","",E40*M40) -> 19218.76 | O40: 1364 | P40: =SUMIF($A$2:$A$200,A40,$E$2:$E$200) -> 1364
A41: 984638066 | B41: PRIMUS 300ML | C41: 6330 | D41: 46630 | E41: 221 | F41: =IF(D41="","",ROUND((D41-Parametri!$B$3)/30.4375,1)) -> 11.1 | G41: =IF(P41<>O41,"Mancante temporaneamente (difformità)",IF(D41="","Mancante (senza scadenza)",IF(D41<Parametri!$B$3,"Scaduto",IF(H41="","Prezzo mancante","Disponibile")))) -> Disponibile | H41: 45 | I41: =Parametri!$B$4 -> 0.1 | J41: =IF(H41="","",ROUND(H41/(1+I41),2)) -> 40.91 | K41: =IF(G41<>"Disponibile","",IF(D41>=EDATE(Parametri!$B$3,Parametri!$B$9),Parametri!$C$9,IF(D41>=EDATE(Parametri!$B$3,Parametri!$B$10),Parametri!$C$10,Parametri!$C$11))) -> 0.38 | L41: =IF(K41="","",ROUND(H41*(1-K41),2)) -> 27.9 | M41: =IF(K41="","",ROUND(L41/(1+I41),2)) -> 25.36 | N41: =IF(M41="","",E41*M41) -> 5604.56 | O41: 1221 | P41: =SUMIF($A$2:$A$200,A41,$E$2:$E$200) -> 1221
A42: 984638066 | B42: PRIMUS 300ML | C42: 7665 | D42: 46965 | E42: 1000 | F42: =IF(D42="","",ROUND((D42-Parametri!$B$3)/30.4375,1)) -> 22.1 | G42: =IF(P42<>O42,"Mancante temporaneamente (difformità)",IF(D42="","Mancante (senza scadenza)",IF(D42<Parametri!$B$3,"Scaduto",IF(H42="","Prezzo mancante","Disponibile")))) -> Disponibile | H42: 45 | I42: =Parametri!$B$4 -> 0.1 | J42: =IF(H42="","",ROUND(H42/(1+I42),2)) -> 40.91 | K42: =IF(G42<>"Disponibile","",IF(D42>=EDATE(Parametri!$B$3,Parametri!$B$9),Parametri!$C$9,IF(D42>=EDATE(Parametri!$B$3,Parametri!$B$10),Parametri!$C$10,Parametri!$C$11))) -> 0.38 | L42: =IF(K42="","",ROUND(H42*(1-K42),2)) -> 27.9 | M42: =IF(K42="","",ROUND(L42/(1+I42),2)) -> 25.36 | N42: =IF(M42="","",E42*M42) -> 25360 | O42: 1221 | P42: =SUMIF($A$2:$A$200,A42,$E$2:$E$200) -> 1221
A43: 990071591 | B43: PRIMUS FITO 20CPS | C43: L-01 | D43: 47177 | E43: 968 | F43: =IF(D43="","",ROUND((D43-Parametri!$B$3)/30.4375,1)) -> 29 | G43: =IF(P43<>O43,"Mancante temporaneamente (difformità)",IF(D43="","Mancante (senza scadenza)",IF(D43<Parametri!$B$3,"Scaduto",IF(H43="","Prezzo mancante","Disponibile")))) -> Disponibile | H43: 22.5 | I43: =Parametri!$B$4 -> 0.1 | J43: =IF(H43="","",ROUND(H43/(1+I43),2)) -> 20.45 | K43: =IF(G43<>"Disponibile","",IF(D43>=EDATE(Parametri!$B$3,Parametri!$B$9),Parametri!$C$9,IF(D43>=EDATE(Parametri!$B$3,Parametri!$B$10),Parametri!$C$10,Parametri!$C$11))) -> 0.38 | L43: =IF(K43="","",ROUND(H43*(1-K43),2)) -> 13.95 | M43: =IF(K43="","",ROUND(L43/(1+I43),2)) -> 12.68 | N43: =IF(M43="","",E43*M43) -> 12274.24 | O43: 968 | P43: =SUMIF($A$2:$A$200,A43,$E$2:$E$200) -> 968
A44: 988258784 | B44: PRIMUS TASK 10STICKPACK | C44: 5520 | D44: 46599 | E44: 908 | F44: =IF(D44="","",ROUND((D44-Parametri!$B$3)/30.4375,1)) -> 10.1 | G44: =IF(P44<>O44,"Mancante temporaneamente (difformità)",IF(D44="","Mancante (senza scadenza)",IF(D44<Parametri!$B$3,"Scaduto",IF(H44="","Prezzo mancante","Disponibile")))) -> Disponibile | H44: 24 | I44: =Parametri!$B$4 -> 0.1 | J44: =IF(H44="","",ROUND(H44/(1+I44),2)) -> 21.82 | K44: =IF(G44<>"Disponibile","",IF(D44>=EDATE(Parametri!$B$3,Parametri!$B$9),Parametri!$C$9,IF(D44>=EDATE(Parametri!$B$3,Parametri!$B$10),Parametri!$C$10,Parametri!$C$11))) -> 0.38 | L44: =IF(K44="","",ROUND(H44*(1-K44),2)) -> 14.88 | M44: =IF(K44="","",ROUND(L44/(1+I44),2)) -> 13.53 | N44: =IF(M44="","",E44*M44) -> 12285.24 | O44: 5892 | P44: =SUMIF($A$2:$A$200,A44,$E$2:$E$200) -> 5892
...

Sheet Da sistemare
A1: Prodotto | B1: Problema | C1: Cosa succede nel portale
A2: ELIVID 60CPR | B2: Lotti 297 + 2.020 = 2.317, totale prodotto 2.314 | C2: Prodotto mancante temporaneamente finché lotti e totale non coincidono
A3: RIPARASE CREMA 50ML (lotto L78) | B3: Senza data di scadenza | C3: Mostrato come mancante
A4: RIPARASE PLUS CREMA 100ML (lotto 10p) | B4: Senza data di scadenza | C4: Mostrato come mancante
A5: INFANTUSS 200ML | B5: Prezzo al pubblico assente nel listino | C5: Non visibile alle farmacie finché non si inserisce il prezzo
A6: NIAGARA COLLUTORIO 200ML | B6: Prezzo al pubblico assente nel listino | C6: Non visibile alle farmacie finché non si inserisce il prezzo
A7: OMEGAREX 20STICK PACK | B7: Prezzo al pubblico assente nel listino | C7: Non visibile alle farmacie finché non si inserisce il prezzo
A8: REGENERIS EMULGEL CR CICATRICI | B8: Prezzo al pubblico assente nel listino | C8: Non visibile alle farmacie finché non si inserisce il prezzo
A9: SPARTA PAPPA REALE 10STICKPACK | B9: Prezzo al pubblico assente nel listino | C9: Non visibile alle farmacie finché non si inserisce il prezzo
A10: VITABIM 200ML | B10: Prezzo al pubblico assente nel listino | C10: Non visibile alle farmacie finché non si inserisce il prezzo
